Workbook

Sheet Income Statement
A1: TCS Consolidated Income Statement (USD Million)
A2: Source: IFRS Accounting Standards
A4: Particulars | B4: FY 2023 | C4: FY 2024 | D4: FY 2025
A5: REVENUE
A6: IT and Consultancy Services | B6: 27927 | C6: 29080 | D6: 30179
A7: Equipment & Software Licenses
A8: Total Revenue | B8: 27927 | C8: 29080 | D8: 30179
A10: COST OF REVENUES
A11: Employee Cost | B11: 12284 | C11: 13188 | D11: 13668
A12: Fees to External Consultants | B12: 2559 | C12: 1810 | D12: 1305
A13: Equipment & Software Cost | B13: 231 | C13: 446 | D13: 1376
A14: Depreciation | B14: 474 | C14: 461 | D14: 483
A15: Travel | B15: 225 | C15: 249 | D15: 276
A16: Communication | B16: 186 | C16: 178 | D16: 190
A17: Facility Expenses | B17: 205 | C17: 233 | D17: 255
A18: Other Expenses | B18: 720 | C18: 770 | D18: 885
A19: Total Cost of Revenues | B19: 16884 | C19: 17335 | D19: 18438
A21: GROSS PROFIT | B21: 11043 | C21: 11745 | D21: 11741
A23: OPERATING EXPENSES
A24: Employee Cost | B24: 3515 | C24: 3729 | D24: 3565
A25: Fees to External Consultants | B25: 86 | C25: 101 | D25: 77
A26: Provision for Doubtful Debts | B26: 17 | C26: 14 | D26: 15
A27: Depreciation | B27: 149 | C27: 141 | D27: 136
A28: Facility Expenses | B28: 124 | C28: 142 | D28: 153
A29: Travel | B29: 106 | C29: 110 | D29: 104
A30: Communication | B30: 92 | C30: 95 | D30: 90
A31: Other Expenses | B31: 240 | C31: 255 | D31: 253
A32: Total Operating Expenses | B32: 4329 | C32: 4587 | D32: 4393
A34: OPERATING INCOME | B34: 6714 | C34: 7158 | D34: 7348
A36: Other Income / (Expense) | B36: 332 | C36: 451 | D36: 374
A38: INCOME BEFORE TAX | B38: 7046 | C38: 7609 | D38: 7722
... A46: NET PROFIT | B46: 5219 | C46: 5623 | D46: 5739
A48: METRICS
A49: Earnings Per Share (EPS) | B49: 1.43 | C49: 1.54 | D49: 1.59

Sheet Balance Sheet
A1: TCS CONSOLIDATED BALANCE SHEET (USD Million)
A2: As per IFRS Accounting Standards | USD Million
A3: (As at March 31)
A5: Particulars | B5: FY 2023 | C5: FY 2024 | D5: FY 2025
A6: A. ASSETS
A8: I. CURRENT ASSETS
A9: 1. Cash and Cash Equivalents | B9: 866 | C9: 1081 | D9: 976
A10: 2. Bank Deposits | B10: 392 | C10: 456 | D10: 727
A11: 3. Trade Receivables | B11: 4992 | C11: 5328 | D11: 5869
A12: 4. Investments (Current) | B12: 4487 | C12: 3776 | D12: 3592
A13: 5. Other Current Financial Assets | B13: 405 | C13: 320 | D13: 428
A14: 6. Unbilled Receivables | B14: 1083 | C14: 1096 | D14: 1042
A15: 7. Current Income Tax Assets | B15: 1 | C15: 18 | D15: 30
A16: 8. Other Current Assets | B16: 1185 | C16: 1475 | D16: 1730
A17: Total Current Assets (I) | B17: =SUM(B9:B16) -> 13411 | C17: =SUM(C9:C16) -> 13550 | D17: =SUM(D9:D16) -> 14394
A19: II. NON-CURRENT ASSETS
A20: A. Financial Assets
A21: 1. Bank Deposits (Non-Current) | B21: 162 | C21: 270 | D21: 200
A22: 2. Investments (Non-Current) | B22: 32 | C22: 34 | D22: 32
A23: 3. Trade Receivables (Non-Current) | B23: 18 | C23: 15 | D23: 11
A24: 4. Unbilled Receivables (Non-Current) | B24: 24 | C24: 2 | D24: 4
A25: 5. Other Non-Current Financial Assets | B25: 120 | C25: 123 | D25: 123
A26: B. Tax Assets
A27: 6. Non-Current Income Tax Assets | B27: 314 | C27: 192 | D27: 184
A28: 7. Deferred Income Tax Assets | B28: 399 | C28: 405 | D28: 415
A29: C. Property, Plant & Equipment
A30: 8. Property, Plant and Equipment | B30: 1410 | C30: 1346 | D30: 1514
A31: D. Intangible Assets & Goodwill
A32: 9. Other Intangible Assets | B32: 105 | C32: 61 | D32: 109
A33: 10. Right-of-Use Assets | B33: 919 | C33: 946 | D33: 1086
A34: 11. Goodwill | B34: 488 | C34: 478 | D34: 471
A35: E. Other Assets
A36: 12. Other Non-Current Assets | B36: 326 | C36: 394 | D36: 388
A37: Total Non-Current Assets (II) | B37: =SUM(B21:B25,B27:B28,B30,B32:B34,B36) -> 4317 | C37: =SUM(C21:C25,C27:C28,C30,C32:C34,C36) -> 4266 | D37: =SUM(D21:D25,D27:D28,D30,D32:D34,D36) -> 4537
A39: TOTAL ASSETS (I + II) | B39: =B17+B37 -> 17728 | C39: =C17+C37 -> 17816 | D39: =D17+D37 -> 18931
A42: B. LIABILITIES AND SHAREHOLDERS EQUITY
A44: I. CURRENT LIABILITIES
A45: 1. Trade and Other Payables | B45: 1278 | C45: 1197 | D45: 1628
A46: 2. Borrowings (Current) | B46: 0 | C46: 0 | D46: 0
A47: 3. Lease Liabilities (Current) | B47: 181 | C47: 180 | D47: 182
...

Sheet Cash Flow Statement
A1: TCS CONSOLIDATED CASH FLOW STATEMENT
A2: (Indirect Method - USD Million)
A4: Particulars | B4: FY 2023 | C4: FY 2024 | D4: FY 2025
A5: A. CASH FLOWS FROM OPERATING ACTIVITIES
A7: Net Profit before Tax | B7: 7046 | C7: 7609 | D7: 7722
A8: Adjustments:
A9: Depreciation & Amortization | B9: 623 | C9: 602 | D9: 619
A10: Finance Costs | B10: 0 | C10: 0 | D10: 0
A11: Other non-cash charges | B11: 50 | C11: 45 | D11: 55
A12: Operating Profit Before Working Capital Changes | B12: =B7+B9+B10+B11 -> 7719 | C12: =C7+C9+C10+C11 -> 8256 | D12: =D7+D9+D10+D11 -> 8396
A13: Changes in Working Capital:
A14: (Increase) / Decrease in Trade Receivables | B14: -336 | C14: -541 | D14: -50
A15: (Increase) / Decrease in Other Receivables | B15: 100 | C15: 50 | D15: 80
A16: Increase / (Decrease) in Trade Payables | B16: -81 | C16: 431 | D16: 200
A17: Increase / (Decrease) in Other Payables | B17: 150 | C17: 100 | D17: 120
A18: Cash Generated from Operating Activities | B18: =B12+SUM(B14:B17) -> 7552 | C18: =C12+SUM(C14:C17) -> 8296 | D18: =D12+SUM(D14:D17) -> 8746
A19: Income Tax Paid | B19: -1808 | C19: -1963 | D19: -1954
A21: Net Cash from Operating Activities | B21: =B18+B19 -> 5744 | C21: =C18+C19 -> 6333 | D21: =D18+D19 -> 6792
A23: B. CASH FLOWS FROM INVESTING ACTIVITIES
A25: (Purchases) / Sales of Property, Plant & Equipment | B25: -300 | C25: -280 | D25: -320
A26: (Purchases) / Sales of Investments | B26: 711 | C26: 184 | D26: 100
A27: Interest Received | B27: 80 | C27: 90 | D27: 100
A28: Dividends Received | B28: 60 | C28: 70 | D28: 80
A30: Net Cash from Investing Activities | B30: =SUM(B25:B28) -> 551 | C30: =SUM(C25:C28) -> 64 | D30: =SUM(D25:D28) -> -40
A32: C. CASH FLOWS FROM FINANCING ACTIVITIES
A34: Proceeds from Borrowings | B34: 0 | C34: 0 | D34: 0
A35: Repayment of Borrowings | B35: 0 | C35: 0 | D35: 0
A36: Lease Payments | B36: -100 | C36: -105 | D36: -110
A37: Dividends Paid | B37: -1300 | C37: -1400 | D37: -1500
A38: Employee Share-based Payments | B38: 50 | C38: 60 | D38: 70
A40: Net Cash from Financing Activities | B40: =SUM(B34:B38) -> -1350 | C40: =SUM(C34:C38) -> -1445 | D40: =SUM(D34:D38) -> -1540
A42: Net Increase / (Decrease) in Cash | B42: =B21+B30+B40 -> 4945 | C42: =C21+C30+C40 -> 4952 | D42: =D21+D30+D40 -> 5212
A43: Cash and Cash Equivalents at Beginning of Year | B43: 866 | C43: ='Balance Sheet'!C9 -> 1081 | D43: ='Balance Sheet'!D9 -> 976
A44: Cash and Cash Equivalents at End of Year | B44: =B43+B42 -> 5811 | C44: =C43+C42 -> 6033 | D44: =D43+D42 -> 6188

Sheet Ratio Analysis
A1: TCS — KEY FINANCIAL RATIOS (USD Million)
A2: Source: Income Statement & Balance Sheet (IFRS, USD Million) | FY 2023–FY 2025
A4: Ratio | B4: FY 2023 | C4: FY 2024 | D4: FY 2025 | E4: Formula / Notes
A5: PROFITABILITY RATIOS
A6: 1. Gross Profit Margin | B6: ='Income Statement'!B21/'Income Statement'!B8 -> 0.39542378 | C6: ='Income Statement'!C21/'Income Statement'!C8 -> 0.40388583 | D6: ='Income Statement'!D21/'Income Statement'!D8 -> 0.38904536 | E6: Gross Profit ÷ Total Revenue
A7: 2. Operating Profit Margin (EBIT Margin) | B7: ='Income Statement'!B34/'Income Statement'!B8 -> 0.2404125 | C7: ='Income Statement'!C34/'Income Statement'!C8 -> 0.24614856 | D7: ='Income Statement'!D34/'Income Statement'!D8 -> 0.24348057 | E7: Operating Income ÷ Total Revenue
A8: 3. Net Profit Margin | B8: ='Income Statement'!B46/'Income Statement'!B8 -> 0.18688008 | C8: ='Income Statement'!C46/'Income Statement'!C8 -> 0.19336314 | D8: ='Income Statement'!D46/'Income Statement'!D8 -> 0.19016535 | E8: Net Profit ÷ Total Revenue
A9: RETURN RATIOS
A10: 4. Return on Equity (ROE) | B10: ='Income Statement'!B46/('Balance Sheet'!B71+'Balance Sheet'!B74+'Balance Sheet'!B75+'Balance Sheet'!B78) -> 0.45986431 | C10: ='Income Statement'!C46/('Balance Sheet'!C71+'Balance Sheet'!C74+'Balance Sheet'!C75+'Balance Sheet'!C78) -> 0.50182954 | D10: ='Income Statement'!D46/('Balance Sheet'!D71+'Balance Sheet'!D74+'Balance Sheet'!D75+'Balance Sheet'!D78) -> 0.50082904 | E10: Net Profit ÷ Total Shareholders Equity (incl. NCI)
A11: 5. Return on Assets (ROA) | B11: ='Income Statement'!B46/(SUM('Balance Sheet'!B9:B16)+SUM('Balance Sheet'!B21:B36)) -> 0.29439305 | C11: ='Income Statement'!C46/(SUM('Balance Sheet'!C9:C16)+SUM('Balance Sheet'!C21:C36)) -> 0.31561518 | D11: ='Income Statement'!D46/(SUM('Balance Sheet'!D9:D16)+SUM('Balance Sheet'!D21:D36)) -> 0.30315356 | E11: Net Profit ÷ Total Assets
A12: LIQUIDITY RATIOS
A13: 6. Current Ratio | B13: =SUM('Balance Sheet'!B9:B16)/SUM('Balance Sheet'!B45,'Balance Sheet'!B47:B53) -> 2.5318105 | C13: =SUM('Balance Sheet'!C9:C16)/SUM('Balance Sheet'!C45,'Balance Sheet'!C47:C53) -> 2.4507144 | D13: =SUM('Balance Sheet'!D9:D16)/SUM('Balance Sheet'!D45,'Balance Sheet'!D47:D53) -> 2.3208642 | E13: Current Assets ÷ Current Liabilities
A14: 7. Quick Ratio (Acid Test) | B14: =(SUM('Balance Sheet'!B9:B16)-'Balance Sheet'!B16)/SUM('Balance Sheet'!B45,'Balance Sheet'!B47:B53) -> 2.3080989 | C14: =(SUM('Balance Sheet'!C9:C16)-'Balance Sheet'!C16)/SUM('Balance Sheet'!C45,'Balance Sheet'!C47:C53) -> 2.1839392 | D14: =(SUM('Balance Sheet'!D9:D16)-'Balance Sheet'!D16)/SUM('Balance Sheet'!D45,'Balance Sheet'!D47:D53) -> 2.041922 | E14: (Current Assets − Other Current Assets) ÷ Current Liabilities
A15: LEVERAGE / SOLVENCY RATIOS
A16: 8. Debt-to-Equity Ratio | B16: =('Balance Sheet'!B47+'Balance Sheet'!B58)/('Balance Sheet'!B71+'Balance Sheet'!B74+'Balance Sheet'!B75+'Balance Sheet'!B78) -> 0.082386113 | C16: =('Balance Sheet'!C47+'Balance Sheet'!C58)/('Balance Sheet'!C71+'Balance Sheet'!C74+'Balance Sheet'!C75+'Balance Sheet'!C78) -> 0.085765283 | D16: =('Balance Sheet'!D47+'Balance Sheet'!D58)/('Balance Sheet'!D71+'Balance Sheet'!D74+'Balance Sheet'!D75+'Balance Sheet'!D78) -> 0.095907147 | E16: Lease Liabilities (Cur. + Non-Cur.) ÷ Shareholders Equity (TCS has zero financial debt)
A17: 9. Interest Coverage Ratio (EBIT / Finance Costs) | B17: N/A | C17: N/A | D17: N/A | E17: N/A — TCS carries no financial debt; finance costs = 0

Sheet Revenue Profit Trend
A1: TCS — Revenue & Profit Trend (USD Million)
A2: Source: TCS Consolidated Income Statement | IFRS Accounting Standards
A4: Metric | B4: FY 2023 | C4: FY 2024 | D4: FY 2025 | E4: FY23→FY24 Growth | F4: FY24→FY25 Growth
A5: Total Revenue | B5: 27927 | C5: 29080 | D5: 30179 | E5: =(C5-B5)/B5 -> 0.04128621 | F5: =(D5-C5)/C5 -> 0.037792297
A6: Gross Profit | B6: 11043 | C6: 11745 | D6: 11741 | E6: =(C6-B6)/B6 -> 0.063569682 | F6: =(D6-C6)/C6 -> -0.00034057046
A7: Operating Income | B7: 6714 | C7: 7158 | D7: 7348 | E7: =(C7-B7)/B7 -> 0.066130474 | F7: =(D7-C7)/C7 -> 0.026543727
A8: Net Profit | B8: 5219 | C8: 5623 | D8: 5739 | E8: =(C8-B8)/B8 -> 0.077409465 | F8: =(D8-C8)/C8 -> 0.020629557
A10: Margin Analysis | B10: FY 2023 | C10: FY 2024 | D10: FY 2025 | E10: FY23→FY24 Δ | F10: FY24→FY25 Δ
A11: Gross Margin | B11: =B5/B5 -> 1 | C11: =C5/C5 -> 1 | D11: =D5/D5 -> 1 | E11: =C11-B11 -> 0 | F11: =D11-C11 -> 0
A12: Operating Margin | B12: =B7/B5 -> 0.2404125 | C12: =C7/C5 -> 0.24614856 | D12: =D7/D5 -> 0.24348057 | E12: =C12-B12 -> 0.0057360517 | F12: =D12-C12 -> -0.0026679898
A13: Net Profit Margin | B13: =B8/B5 -> 0.18688008 | C13: =C8/C5 -> 0.19336314 | D13: =D8/D5 -> 0.19016535 | E13: =C13-B13 -> 0.006483056 | F13: =D13-C13 -> -0.0031977894
